2025-05-23 09:05:57,076 INFO    MainThread:43512 [wandb_setup.py:_flush():70] Current SDK version is 0.19.11
2025-05-23 09:05:57,076 INFO    MainThread:43512 [wandb_setup.py:_flush():70] Configure stats pid to 43512
2025-05-23 09:05:57,076 INFO    MainThread:43512 [wandb_setup.py:_flush():70] Loading settings from C:\Users\natth\.config\wandb\settings
2025-05-23 09:05:57,076 INFO    MainThread:43512 [wandb_setup.py:_flush():70] Loading settings from C:\D\Sheet_Lecture\DRL\FRA503-Final-Project\wandb\settings
2025-05-23 09:05:57,077 INFO    MainThread:43512 [wandb_setup.py:_flush():70] Loading settings from environment variables
2025-05-23 09:05:57,077 INFO    MainThread:43512 [wandb_init.py:setup_run_log_directory():724] Logging user logs to C:\D\Sheet_Lecture\DRL\FRA503-Final-Project\wandb\run-20250523_090557-cxg3jgr2\logs\debug.log
2025-05-23 09:05:57,078 INFO    MainThread:43512 [wandb_init.py:setup_run_log_directory():725] Logging internal logs to C:\D\Sheet_Lecture\DRL\FRA503-Final-Project\wandb\run-20250523_090557-cxg3jgr2\logs\debug-internal.log
2025-05-23 09:05:57,078 INFO    MainThread:43512 [wandb_init.py:init():852] calling init triggers
2025-05-23 09:05:57,078 INFO    MainThread:43512 [wandb_init.py:init():857] wandb.init called with sweep_config: {}
config: {'_wandb': {}}
2025-05-23 09:05:57,078 INFO    MainThread:43512 [wandb_init.py:init():893] starting backend
2025-05-23 09:05:57,078 INFO    MainThread:43512 [wandb_init.py:init():897] sending inform_init request
2025-05-23 09:05:57,126 INFO    MainThread:43512 [backend.py:_multiprocessing_setup():101] multiprocessing start_methods=spawn, using: spawn
2025-05-23 09:05:57,126 INFO    MainThread:43512 [wandb_init.py:init():907] backend started and connected
2025-05-23 09:05:57,127 INFO    MainThread:43512 [wandb_init.py:init():1005] updated telemetry
2025-05-23 09:05:57,177 INFO    MainThread:43512 [wandb_init.py:init():1029] communicating run to backend with 90.0 second timeout
2025-05-23 09:05:58,915 INFO    MainThread:43512 [wandb_init.py:init():1104] starting run threads in backend
2025-05-23 09:05:59,169 INFO    MainThread:43512 [wandb_run.py:_console_start():2573] atexit reg
2025-05-23 09:05:59,169 INFO    MainThread:43512 [wandb_run.py:_redirect():2421] redirect: wrap_raw
2025-05-23 09:05:59,169 INFO    MainThread:43512 [wandb_run.py:_redirect():2490] Wrapping output streams.
2025-05-23 09:05:59,169 INFO    MainThread:43512 [wandb_run.py:_redirect():2513] Redirects installed.
2025-05-23 09:05:59,172 INFO    MainThread:43512 [wandb_init.py:init():1150] run started, returning control to user process
2025-05-23 09:13:31,544 INFO    MsgRouterThr:43512 [mailbox.py:close():129] [no run ID] Closing mailbox, abandoning 1 handles.
2025-05-23 09:13:31,685 ERROR   Thread-38 :43512 [redirect.py:_on_write():664] [no run ID] error in stdout callback
Traceback (most recent call last):
  File "C:\Users\natth\AppData\Roaming\Python\Python312\site-packages\wandb\sdk\lib\redirect.py", line 662, in _on_write
    cb(written_data)
  File "C:\Users\natth\AppData\Roaming\Python\Python312\site-packages\wandb\sdk\wandb_run.py", line 2494, in <lambda>
    lambda data: self._console_raw_callback("stdout", data),
                 ^^^^^^^^^^^^^^^^^^^^^^^^^^^^^^^^^^^^^^^^^^
  File "C:\Users\natth\AppData\Roaming\Python\Python312\site-packages\wandb\sdk\wandb_run.py", line 406, in wrapper
    return func(self, *args, **kwargs)
           ^^^^^^^^^^^^^^^^^^^^^^^^^^^
  File "C:\Users\natth\AppData\Roaming\Python\Python312\site-packages\wandb\sdk\wandb_run.py", line 464, in wrapper_fn
    return func(self, *args, **kwargs)
           ^^^^^^^^^^^^^^^^^^^^^^^^^^^
  File "C:\Users\natth\AppData\Roaming\Python\Python312\site-packages\wandb\sdk\wandb_run.py", line 1639, in _console_raw_callback
    self._backend.interface.publish_output_raw(name, data)
  File "C:\Users\natth\AppData\Roaming\Python\Python312\site-packages\wandb\sdk\interface\interface.py", line 762, in publish_output_raw
    self._publish_output_raw(o)
  File "C:\Users\natth\AppData\Roaming\Python\Python312\site-packages\wandb\sdk\interface\interface_shared.py", line 38, in _publish_output_raw
    self._publish(rec)
  File "C:\Users\natth\AppData\Roaming\Python\Python312\site-packages\wandb\sdk\interface\interface_sock.py", line 39, in _publish
    self._sock_client.send_record_publish(record)
  File "C:\Users\natth\AppData\Roaming\Python\Python312\site-packages\wandb\sdk\lib\sock_client.py", line 174, in send_record_publish
    self.send_server_request(server_req)
  File "C:\Users\natth\AppData\Roaming\Python\Python312\site-packages\wandb\sdk\lib\sock_client.py", line 154, in send_server_request
    self._send_message(msg)
  File "C:\Users\natth\AppData\Roaming\Python\Python312\site-packages\wandb\sdk\lib\sock_client.py", line 151, in _send_message
    self._sendall_with_error_handle(header + data)
  File "C:\Users\natth\AppData\Roaming\Python\Python312\site-packages\wandb\sdk\lib\sock_client.py", line 130, in _sendall_with_error_handle
    sent = self._sock.send(data)
           ^^^^^^^^^^^^^^^^^^^^^
ConnectionAbortedError: [WinError 10053] An established connection was aborted by the software in your host machine
2025-05-23 09:13:31,798 ERROR   Thread-38 :43512 [redirect.py:_on_write():664] [no run ID] error in stdout callback
Traceback (most recent call last):
  File "C:\Users\natth\AppData\Roaming\Python\Python312\site-packages\wandb\sdk\lib\redirect.py", line 662, in _on_write
    cb(written_data)
  File "C:\Users\natth\AppData\Roaming\Python\Python312\site-packages\wandb\sdk\wandb_run.py", line 2494, in <lambda>
    lambda data: self._console_raw_callback("stdout", data),
                 ^^^^^^^^^^^^^^^^^^^^^^^^^^^^^^^^^^^^^^^^^^
  File "C:\Users\natth\AppData\Roaming\Python\Python312\site-packages\wandb\sdk\wandb_run.py", line 406, in wrapper
    return func(self, *args, **kwargs)
           ^^^^^^^^^^^^^^^^^^^^^^^^^^^
  File "C:\Users\natth\AppData\Roaming\Python\Python312\site-packages\wandb\sdk\wandb_run.py", line 464, in wrapper_fn
    return func(self, *args, **kwargs)
           ^^^^^^^^^^^^^^^^^^^^^^^^^^^
  File "C:\Users\natth\AppData\Roaming\Python\Python312\site-packages\wandb\sdk\wandb_run.py", line 1639, in _console_raw_callback
    self._backend.interface.publish_output_raw(name, data)
  File "C:\Users\natth\AppData\Roaming\Python\Python312\site-packages\wandb\sdk\interface\interface.py", line 762, in publish_output_raw
    self._publish_output_raw(o)
  File "C:\Users\natth\AppData\Roaming\Python\Python312\site-packages\wandb\sdk\interface\interface_shared.py", line 38, in _publish_output_raw
    self._publish(rec)
  File "C:\Users\natth\AppData\Roaming\Python\Python312\site-packages\wandb\sdk\interface\interface_sock.py", line 39, in _publish
    self._sock_client.send_record_publish(record)
  File "C:\Users\natth\AppData\Roaming\Python\Python312\site-packages\wandb\sdk\lib\sock_client.py", line 174, in send_record_publish
    self.send_server_request(server_req)
  File "C:\Users\natth\AppData\Roaming\Python\Python312\site-packages\wandb\sdk\lib\sock_client.py", line 154, in send_server_request
    self._send_message(msg)
  File "C:\Users\natth\AppData\Roaming\Python\Python312\site-packages\wandb\sdk\lib\sock_client.py", line 151, in _send_message
    self._sendall_with_error_handle(header + data)
  File "C:\Users\natth\AppData\Roaming\Python\Python312\site-packages\wandb\sdk\lib\sock_client.py", line 130, in _sendall_with_error_handle
    sent = self._sock.send(data)
           ^^^^^^^^^^^^^^^^^^^^^
ConnectionAbortedError: [WinError 10053] An established connection was aborted by the software in your host machine
2025-05-23 09:13:31,908 ERROR   Thread-38 :43512 [redirect.py:_on_write():664] [no run ID] error in stdout callback
Traceback (most recent call last):
  File "C:\Users\natth\AppData\Roaming\Python\Python312\site-packages\wandb\sdk\lib\redirect.py", line 662, in _on_write
    cb(written_data)
  File "C:\Users\natth\AppData\Roaming\Python\Python312\site-packages\wandb\sdk\wandb_run.py", line 2494, in <lambda>
    lambda data: self._console_raw_callback("stdout", data),
                 ^^^^^^^^^^^^^^^^^^^^^^^^^^^^^^^^^^^^^^^^^^
  File "C:\Users\natth\AppData\Roaming\Python\Python312\site-packages\wandb\sdk\wandb_run.py", line 406, in wrapper
    return func(self, *args, **kwargs)
           ^^^^^^^^^^^^^^^^^^^^^^^^^^^
  File "C:\Users\natth\AppData\Roaming\Python\Python312\site-packages\wandb\sdk\wandb_run.py", line 464, in wrapper_fn
    return func(self, *args, **kwargs)
           ^^^^^^^^^^^^^^^^^^^^^^^^^^^
  File "C:\Users\natth\AppData\Roaming\Python\Python312\site-packages\wandb\sdk\wandb_run.py", line 1639, in _console_raw_callback
    self._backend.interface.publish_output_raw(name, data)
  File "C:\Users\natth\AppData\Roaming\Python\Python312\site-packages\wandb\sdk\interface\interface.py", line 762, in publish_output_raw
    self._publish_output_raw(o)
  File "C:\Users\natth\AppData\Roaming\Python\Python312\site-packages\wandb\sdk\interface\interface_shared.py", line 38, in _publish_output_raw
    self._publish(rec)
  File "C:\Users\natth\AppData\Roaming\Python\Python312\site-packages\wandb\sdk\interface\interface_sock.py", line 39, in _publish
    self._sock_client.send_record_publish(record)
  File "C:\Users\natth\AppData\Roaming\Python\Python312\site-packages\wandb\sdk\lib\sock_client.py", line 174, in send_record_publish
    self.send_server_request(server_req)
  File "C:\Users\natth\AppData\Roaming\Python\Python312\site-packages\wandb\sdk\lib\sock_client.py", line 154, in send_server_request
    self._send_message(msg)
  File "C:\Users\natth\AppData\Roaming\Python\Python312\site-packages\wandb\sdk\lib\sock_client.py", line 151, in _send_message
    self._sendall_with_error_handle(header + data)
  File "C:\Users\natth\AppData\Roaming\Python\Python312\site-packages\wandb\sdk\lib\sock_client.py", line 130, in _sendall_with_error_handle
    sent = self._sock.send(data)
           ^^^^^^^^^^^^^^^^^^^^^
ConnectionAbortedError: [WinError 10053] An established connection was aborted by the software in your host machine
2025-05-23 09:13:32,021 ERROR   Thread-38 :43512 [redirect.py:_on_write():664] [no run ID] error in stdout callback
Traceback (most recent call last):
  File "C:\Users\natth\AppData\Roaming\Python\Python312\site-packages\wandb\sdk\lib\redirect.py", line 662, in _on_write
    cb(written_data)
  File "C:\Users\natth\AppData\Roaming\Python\Python312\site-packages\wandb\sdk\wandb_run.py", line 2494, in <lambda>
    lambda data: self._console_raw_callback("stdout", data),
                 ^^^^^^^^^^^^^^^^^^^^^^^^^^^^^^^^^^^^^^^^^^
  File "C:\Users\natth\AppData\Roaming\Python\Python312\site-packages\wandb\sdk\wandb_run.py", line 406, in wrapper
    return func(self, *args, **kwargs)
           ^^^^^^^^^^^^^^^^^^^^^^^^^^^
  File "C:\Users\natth\AppData\Roaming\Python\Python312\site-packages\wandb\sdk\wandb_run.py", line 464, in wrapper_fn
    return func(self, *args, **kwargs)
           ^^^^^^^^^^^^^^^^^^^^^^^^^^^
  File "C:\Users\natth\AppData\Roaming\Python\Python312\site-packages\wandb\sdk\wandb_run.py", line 1639, in _console_raw_callback
    self._backend.interface.publish_output_raw(name, data)
  File "C:\Users\natth\AppData\Roaming\Python\Python312\site-packages\wandb\sdk\interface\interface.py", line 762, in publish_output_raw
    self._publish_output_raw(o)
  File "C:\Users\natth\AppData\Roaming\Python\Python312\site-packages\wandb\sdk\interface\interface_shared.py", line 38, in _publish_output_raw
    self._publish(rec)
  File "C:\Users\natth\AppData\Roaming\Python\Python312\site-packages\wandb\sdk\interface\interface_sock.py", line 39, in _publish
    self._sock_client.send_record_publish(record)
  File "C:\Users\natth\AppData\Roaming\Python\Python312\site-packages\wandb\sdk\lib\sock_client.py", line 174, in send_record_publish
    self.send_server_request(server_req)
  File "C:\Users\natth\AppData\Roaming\Python\Python312\site-packages\wandb\sdk\lib\sock_client.py", line 154, in send_server_request
    self._send_message(msg)
  File "C:\Users\natth\AppData\Roaming\Python\Python312\site-packages\wandb\sdk\lib\sock_client.py", line 151, in _send_message
    self._sendall_with_error_handle(header + data)
  File "C:\Users\natth\AppData\Roaming\Python\Python312\site-packages\wandb\sdk\lib\sock_client.py", line 130, in _sendall_with_error_handle
    sent = self._sock.send(data)
           ^^^^^^^^^^^^^^^^^^^^^
ConnectionAbortedError: [WinError 10053] An established connection was aborted by the software in your host machine
2025-05-23 09:13:32,127 ERROR   Thread-38 :43512 [redirect.py:_on_write():664] [no run ID] error in stdout callback
Traceback (most recent call last):
  File "C:\Users\natth\AppData\Roaming\Python\Python312\site-packages\wandb\sdk\lib\redirect.py", line 662, in _on_write
    cb(written_data)
  File "C:\Users\natth\AppData\Roaming\Python\Python312\site-packages\wandb\sdk\wandb_run.py", line 2494, in <lambda>
    lambda data: self._console_raw_callback("stdout", data),
                 ^^^^^^^^^^^^^^^^^^^^^^^^^^^^^^^^^^^^^^^^^^
  File "C:\Users\natth\AppData\Roaming\Python\Python312\site-packages\wandb\sdk\wandb_run.py", line 406, in wrapper
    return func(self, *args, **kwargs)
           ^^^^^^^^^^^^^^^^^^^^^^^^^^^
  File "C:\Users\natth\AppData\Roaming\Python\Python312\site-packages\wandb\sdk\wandb_run.py", line 464, in wrapper_fn
    return func(self, *args, **kwargs)
           ^^^^^^^^^^^^^^^^^^^^^^^^^^^
  File "C:\Users\natth\AppData\Roaming\Python\Python312\site-packages\wandb\sdk\wandb_run.py", line 1639, in _console_raw_callback
    self._backend.interface.publish_output_raw(name, data)
  File "C:\Users\natth\AppData\Roaming\Python\Python312\site-packages\wandb\sdk\interface\interface.py", line 762, in publish_output_raw
    self._publish_output_raw(o)
  File "C:\Users\natth\AppData\Roaming\Python\Python312\site-packages\wandb\sdk\interface\interface_shared.py", line 38, in _publish_output_raw
    self._publish(rec)
  File "C:\Users\natth\AppData\Roaming\Python\Python312\site-packages\wandb\sdk\interface\interface_sock.py", line 39, in _publish
    self._sock_client.send_record_publish(record)
  File "C:\Users\natth\AppData\Roaming\Python\Python312\site-packages\wandb\sdk\lib\sock_client.py", line 174, in send_record_publish
    self.send_server_request(server_req)
  File "C:\Users\natth\AppData\Roaming\Python\Python312\site-packages\wandb\sdk\lib\sock_client.py", line 154, in send_server_request
    self._send_message(msg)
  File "C:\Users\natth\AppData\Roaming\Python\Python312\site-packages\wandb\sdk\lib\sock_client.py", line 151, in _send_message
    self._sendall_with_error_handle(header + data)
  File "C:\Users\natth\AppData\Roaming\Python\Python312\site-packages\wandb\sdk\lib\sock_client.py", line 130, in _sendall_with_error_handle
    sent = self._sock.send(data)
           ^^^^^^^^^^^^^^^^^^^^^
ConnectionAbortedError: [WinError 10053] An established connection was aborted by the software in your host machine
2025-05-23 09:13:32,234 ERROR   Thread-38 :43512 [redirect.py:_on_write():664] [no run ID] error in stdout callback
Traceback (most recent call last):
  File "C:\Users\natth\AppData\Roaming\Python\Python312\site-packages\wandb\sdk\lib\redirect.py", line 662, in _on_write
    cb(written_data)
  File "C:\Users\natth\AppData\Roaming\Python\Python312\site-packages\wandb\sdk\wandb_run.py", line 2494, in <lambda>
    lambda data: self._console_raw_callback("stdout", data),
                 ^^^^^^^^^^^^^^^^^^^^^^^^^^^^^^^^^^^^^^^^^^
  File "C:\Users\natth\AppData\Roaming\Python\Python312\site-packages\wandb\sdk\wandb_run.py", line 406, in wrapper
    return func(self, *args, **kwargs)
           ^^^^^^^^^^^^^^^^^^^^^^^^^^^
  File "C:\Users\natth\AppData\Roaming\Python\Python312\site-packages\wandb\sdk\wandb_run.py", line 464, in wrapper_fn
    return func(self, *args, **kwargs)
           ^^^^^^^^^^^^^^^^^^^^^^^^^^^
  File "C:\Users\natth\AppData\Roaming\Python\Python312\site-packages\wandb\sdk\wandb_run.py", line 1639, in _console_raw_callback
    self._backend.interface.publish_output_raw(name, data)
  File "C:\Users\natth\AppData\Roaming\Python\Python312\site-packages\wandb\sdk\interface\interface.py", line 762, in publish_output_raw
    self._publish_output_raw(o)
  File "C:\Users\natth\AppData\Roaming\Python\Python312\site-packages\wandb\sdk\interface\interface_shared.py", line 38, in _publish_output_raw
    self._publish(rec)
  File "C:\Users\natth\AppData\Roaming\Python\Python312\site-packages\wandb\sdk\interface\interface_sock.py", line 39, in _publish
    self._sock_client.send_record_publish(record)
  File "C:\Users\natth\AppData\Roaming\Python\Python312\site-packages\wandb\sdk\lib\sock_client.py", line 174, in send_record_publish
    self.send_server_request(server_req)
  File "C:\Users\natth\AppData\Roaming\Python\Python312\site-packages\wandb\sdk\lib\sock_client.py", line 154, in send_server_request
    self._send_message(msg)
  File "C:\Users\natth\AppData\Roaming\Python\Python312\site-packages\wandb\sdk\lib\sock_client.py", line 151, in _send_message
    self._sendall_with_error_handle(header + data)
  File "C:\Users\natth\AppData\Roaming\Python\Python312\site-packages\wandb\sdk\lib\sock_client.py", line 130, in _sendall_with_error_handle
    sent = self._sock.send(data)
           ^^^^^^^^^^^^^^^^^^^^^
ConnectionAbortedError: [WinError 10053] An established connection was aborted by the software in your host machine
2025-05-23 09:13:32,339 ERROR   Thread-38 :43512 [redirect.py:_on_write():664] [no run ID] error in stdout callback
Traceback (most recent call last):
  File "C:\Users\natth\AppData\Roaming\Python\Python312\site-packages\wandb\sdk\lib\redirect.py", line 662, in _on_write
    cb(written_data)
  File "C:\Users\natth\AppData\Roaming\Python\Python312\site-packages\wandb\sdk\wandb_run.py", line 2494, in <lambda>
    lambda data: self._console_raw_callback("stdout", data),
                 ^^^^^^^^^^^^^^^^^^^^^^^^^^^^^^^^^^^^^^^^^^
  File "C:\Users\natth\AppData\Roaming\Python\Python312\site-packages\wandb\sdk\wandb_run.py", line 406, in wrapper
    return func(self, *args, **kwargs)
           ^^^^^^^^^^^^^^^^^^^^^^^^^^^
  File "C:\Users\natth\AppData\Roaming\Python\Python312\site-packages\wandb\sdk\wandb_run.py", line 464, in wrapper_fn
    return func(self, *args, **kwargs)
           ^^^^^^^^^^^^^^^^^^^^^^^^^^^
  File "C:\Users\natth\AppData\Roaming\Python\Python312\site-packages\wandb\sdk\wandb_run.py", line 1639, in _console_raw_callback
    self._backend.interface.publish_output_raw(name, data)
  File "C:\Users\natth\AppData\Roaming\Python\Python312\site-packages\wandb\sdk\interface\interface.py", line 762, in publish_output_raw
    self._publish_output_raw(o)
  File "C:\Users\natth\AppData\Roaming\Python\Python312\site-packages\wandb\sdk\interface\interface_shared.py", line 38, in _publish_output_raw
    self._publish(rec)
  File "C:\Users\natth\AppData\Roaming\Python\Python312\site-packages\wandb\sdk\interface\interface_sock.py", line 39, in _publish
    self._sock_client.send_record_publish(record)
  File "C:\Users\natth\AppData\Roaming\Python\Python312\site-packages\wandb\sdk\lib\sock_client.py", line 174, in send_record_publish
    self.send_server_request(server_req)
  File "C:\Users\natth\AppData\Roaming\Python\Python312\site-packages\wandb\sdk\lib\sock_client.py", line 154, in send_server_request
    self._send_message(msg)
  File "C:\Users\natth\AppData\Roaming\Python\Python312\site-packages\wandb\sdk\lib\sock_client.py", line 151, in _send_message
    self._sendall_with_error_handle(header + data)
  File "C:\Users\natth\AppData\Roaming\Python\Python312\site-packages\wandb\sdk\lib\sock_client.py", line 130, in _sendall_with_error_handle
    sent = self._sock.send(data)
           ^^^^^^^^^^^^^^^^^^^^^
ConnectionAbortedError: [WinError 10053] An established connection was aborted by the software in your host machine
2025-05-23 09:13:32,443 ERROR   Thread-38 :43512 [redirect.py:_on_write():664] [no run ID] error in stdout callback
Traceback (most recent call last):
  File "C:\Users\natth\AppData\Roaming\Python\Python312\site-packages\wandb\sdk\lib\redirect.py", line 662, in _on_write
    cb(written_data)
  File "C:\Users\natth\AppData\Roaming\Python\Python312\site-packages\wandb\sdk\wandb_run.py", line 2494, in <lambda>
    lambda data: self._console_raw_callback("stdout", data),
                 ^^^^^^^^^^^^^^^^^^^^^^^^^^^^^^^^^^^^^^^^^^
  File "C:\Users\natth\AppData\Roaming\Python\Python312\site-packages\wandb\sdk\wandb_run.py", line 406, in wrapper
    return func(self, *args, **kwargs)
           ^^^^^^^^^^^^^^^^^^^^^^^^^^^
  File "C:\Users\natth\AppData\Roaming\Python\Python312\site-packages\wandb\sdk\wandb_run.py", line 464, in wrapper_fn
    return func(self, *args, **kwargs)
           ^^^^^^^^^^^^^^^^^^^^^^^^^^^
  File "C:\Users\natth\AppData\Roaming\Python\Python312\site-packages\wandb\sdk\wandb_run.py", line 1639, in _console_raw_callback
    self._backend.interface.publish_output_raw(name, data)
  File "C:\Users\natth\AppData\Roaming\Python\Python312\site-packages\wandb\sdk\interface\interface.py", line 762, in publish_output_raw
    self._publish_output_raw(o)
  File "C:\Users\natth\AppData\Roaming\Python\Python312\site-packages\wandb\sdk\interface\interface_shared.py", line 38, in _publish_output_raw
    self._publish(rec)
  File "C:\Users\natth\AppData\Roaming\Python\Python312\site-packages\wandb\sdk\interface\interface_sock.py", line 39, in _publish
    self._sock_client.send_record_publish(record)
  File "C:\Users\natth\AppData\Roaming\Python\Python312\site-packages\wandb\sdk\lib\sock_client.py", line 174, in send_record_publish
    self.send_server_request(server_req)
  File "C:\Users\natth\AppData\Roaming\Python\Python312\site-packages\wandb\sdk\lib\sock_client.py", line 154, in send_server_request
    self._send_message(msg)
  File "C:\Users\natth\AppData\Roaming\Python\Python312\site-packages\wandb\sdk\lib\sock_client.py", line 151, in _send_message
    self._sendall_with_error_handle(header + data)
  File "C:\Users\natth\AppData\Roaming\Python\Python312\site-packages\wandb\sdk\lib\sock_client.py", line 130, in _sendall_with_error_handle
    sent = self._sock.send(data)
           ^^^^^^^^^^^^^^^^^^^^^
ConnectionAbortedError: [WinError 10053] An established connection was aborted by the software in your host machine
2025-05-23 09:13:32,547 ERROR   Thread-38 :43512 [redirect.py:_on_write():664] [no run ID] error in stdout callback
Traceback (most recent call last):
  File "C:\Users\natth\AppData\Roaming\Python\Python312\site-packages\wandb\sdk\lib\redirect.py", line 662, in _on_write
    cb(written_data)
  File "C:\Users\natth\AppData\Roaming\Python\Python312\site-packages\wandb\sdk\wandb_run.py", line 2494, in <lambda>
    lambda data: self._console_raw_callback("stdout", data),
                 ^^^^^^^^^^^^^^^^^^^^^^^^^^^^^^^^^^^^^^^^^^
  File "C:\Users\natth\AppData\Roaming\Python\Python312\site-packages\wandb\sdk\wandb_run.py", line 406, in wrapper
    return func(self, *args, **kwargs)
           ^^^^^^^^^^^^^^^^^^^^^^^^^^^
  File "C:\Users\natth\AppData\Roaming\Python\Python312\site-packages\wandb\sdk\wandb_run.py", line 464, in wrapper_fn
    return func(self, *args, **kwargs)
           ^^^^^^^^^^^^^^^^^^^^^^^^^^^
  File "C:\Users\natth\AppData\Roaming\Python\Python312\site-packages\wandb\sdk\wandb_run.py", line 1639, in _console_raw_callback
    self._backend.interface.publish_output_raw(name, data)
  File "C:\Users\natth\AppData\Roaming\Python\Python312\site-packages\wandb\sdk\interface\interface.py", line 762, in publish_output_raw
    self._publish_output_raw(o)
  File "C:\Users\natth\AppData\Roaming\Python\Python312\site-packages\wandb\sdk\interface\interface_shared.py", line 38, in _publish_output_raw
    self._publish(rec)
  File "C:\Users\natth\AppData\Roaming\Python\Python312\site-packages\wandb\sdk\interface\interface_sock.py", line 39, in _publish
    self._sock_client.send_record_publish(record)
  File "C:\Users\natth\AppData\Roaming\Python\Python312\site-packages\wandb\sdk\lib\sock_client.py", line 174, in send_record_publish
    self.send_server_request(server_req)
  File "C:\Users\natth\AppData\Roaming\Python\Python312\site-packages\wandb\sdk\lib\sock_client.py", line 154, in send_server_request
    self._send_message(msg)
  File "C:\Users\natth\AppData\Roaming\Python\Python312\site-packages\wandb\sdk\lib\sock_client.py", line 151, in _send_message
    self._sendall_with_error_handle(header + data)
  File "C:\Users\natth\AppData\Roaming\Python\Python312\site-packages\wandb\sdk\lib\sock_client.py", line 130, in _sendall_with_error_handle
    sent = self._sock.send(data)
           ^^^^^^^^^^^^^^^^^^^^^
ConnectionAbortedError: [WinError 10053] An established connection was aborted by the software in your host machine
2025-05-23 09:13:32,651 ERROR   Thread-38 :43512 [redirect.py:_on_write():664] [no run ID] error in stdout callback
Traceback (most recent call last):
  File "C:\Users\natth\AppData\Roaming\Python\Python312\site-packages\wandb\sdk\lib\redirect.py", line 662, in _on_write
    cb(written_data)
  File "C:\Users\natth\AppData\Roaming\Python\Python312\site-packages\wandb\sdk\wandb_run.py", line 2494, in <lambda>
    lambda data: self._console_raw_callback("stdout", data),
                 ^^^^^^^^^^^^^^^^^^^^^^^^^^^^^^^^^^^^^^^^^^
  File "C:\Users\natth\AppData\Roaming\Python\Python312\site-packages\wandb\sdk\wandb_run.py", line 406, in wrapper
    return func(self, *args, **kwargs)
           ^^^^^^^^^^^^^^^^^^^^^^^^^^^
  File "C:\Users\natth\AppData\Roaming\Python\Python312\site-packages\wandb\sdk\wandb_run.py", line 464, in wrapper_fn
    return func(self, *args, **kwargs)
           ^^^^^^^^^^^^^^^^^^^^^^^^^^^
  File "C:\Users\natth\AppData\Roaming\Python\Python312\site-packages\wandb\sdk\wandb_run.py", line 1639, in _console_raw_callback
    self._backend.interface.publish_output_raw(name, data)
  File "C:\Users\natth\AppData\Roaming\Python\Python312\site-packages\wandb\sdk\interface\interface.py", line 762, in publish_output_raw
    self._publish_output_raw(o)
  File "C:\Users\natth\AppData\Roaming\Python\Python312\site-packages\wandb\sdk\interface\interface_shared.py", line 38, in _publish_output_raw
    self._publish(rec)
  File "C:\Users\natth\AppData\Roaming\Python\Python312\site-packages\wandb\sdk\interface\interface_sock.py", line 39, in _publish
    self._sock_client.send_record_publish(record)
  File "C:\Users\natth\AppData\Roaming\Python\Python312\site-packages\wandb\sdk\lib\sock_client.py", line 174, in send_record_publish
    self.send_server_request(server_req)
  File "C:\Users\natth\AppData\Roaming\Python\Python312\site-packages\wandb\sdk\lib\sock_client.py", line 154, in send_server_request
    self._send_message(msg)
  File "C:\Users\natth\AppData\Roaming\Python\Python312\site-packages\wandb\sdk\lib\sock_client.py", line 151, in _send_message
    self._sendall_with_error_handle(header + data)
  File "C:\Users\natth\AppData\Roaming\Python\Python312\site-packages\wandb\sdk\lib\sock_client.py", line 130, in _sendall_with_error_handle
    sent = self._sock.send(data)
           ^^^^^^^^^^^^^^^^^^^^^
ConnectionAbortedError: [WinError 10053] An established connection was aborted by the software in your host machine
2025-05-23 09:13:32,755 ERROR   Thread-38 :43512 [redirect.py:_on_write():664] [no run ID] error in stdout callback
Traceback (most recent call last):
  File "C:\Users\natth\AppData\Roaming\Python\Python312\site-packages\wandb\sdk\lib\redirect.py", line 662, in _on_write
    cb(written_data)
  File "C:\Users\natth\AppData\Roaming\Python\Python312\site-packages\wandb\sdk\wandb_run.py", line 2494, in <lambda>
    lambda data: self._console_raw_callback("stdout", data),
                 ^^^^^^^^^^^^^^^^^^^^^^^^^^^^^^^^^^^^^^^^^^
  File "C:\Users\natth\AppData\Roaming\Python\Python312\site-packages\wandb\sdk\wandb_run.py", line 406, in wrapper
    return func(self, *args, **kwargs)
           ^^^^^^^^^^^^^^^^^^^^^^^^^^^
  File "C:\Users\natth\AppData\Roaming\Python\Python312\site-packages\wandb\sdk\wandb_run.py", line 464, in wrapper_fn
    return func(self, *args, **kwargs)
           ^^^^^^^^^^^^^^^^^^^^^^^^^^^
  File "C:\Users\natth\AppData\Roaming\Python\Python312\site-packages\wandb\sdk\wandb_run.py", line 1639, in _console_raw_callback
    self._backend.interface.publish_output_raw(name, data)
  File "C:\Users\natth\AppData\Roaming\Python\Python312\site-packages\wandb\sdk\interface\interface.py", line 762, in publish_output_raw
    self._publish_output_raw(o)
  File "C:\Users\natth\AppData\Roaming\Python\Python312\site-packages\wandb\sdk\interface\interface_shared.py", line 38, in _publish_output_raw
    self._publish(rec)
  File "C:\Users\natth\AppData\Roaming\Python\Python312\site-packages\wandb\sdk\interface\interface_sock.py", line 39, in _publish
    self._sock_client.send_record_publish(record)
  File "C:\Users\natth\AppData\Roaming\Python\Python312\site-packages\wandb\sdk\lib\sock_client.py", line 174, in send_record_publish
    self.send_server_request(server_req)
  File "C:\Users\natth\AppData\Roaming\Python\Python312\site-packages\wandb\sdk\lib\sock_client.py", line 154, in send_server_request
    self._send_message(msg)
  File "C:\Users\natth\AppData\Roaming\Python\Python312\site-packages\wandb\sdk\lib\sock_client.py", line 151, in _send_message
    self._sendall_with_error_handle(header + data)
  File "C:\Users\natth\AppData\Roaming\Python\Python312\site-packages\wandb\sdk\lib\sock_client.py", line 130, in _sendall_with_error_handle
    sent = self._sock.send(data)
           ^^^^^^^^^^^^^^^^^^^^^
ConnectionAbortedError: [WinError 10053] An established connection was aborted by the software in your host machine
2025-05-23 09:13:32,859 ERROR   Thread-38 :43512 [redirect.py:_on_write():664] [no run ID] error in stdout callback
Traceback (most recent call last):
  File "C:\Users\natth\AppData\Roaming\Python\Python312\site-packages\wandb\sdk\lib\redirect.py", line 662, in _on_write
    cb(written_data)
  File "C:\Users\natth\AppData\Roaming\Python\Python312\site-packages\wandb\sdk\wandb_run.py", line 2494, in <lambda>
    lambda data: self._console_raw_callback("stdout", data),
                 ^^^^^^^^^^^^^^^^^^^^^^^^^^^^^^^^^^^^^^^^^^
  File "C:\Users\natth\AppData\Roaming\Python\Python312\site-packages\wandb\sdk\wandb_run.py", line 406, in wrapper
    return func(self, *args, **kwargs)
           ^^^^^^^^^^^^^^^^^^^^^^^^^^^
  File "C:\Users\natth\AppData\Roaming\Python\Python312\site-packages\wandb\sdk\wandb_run.py", line 464, in wrapper_fn
    return func(self, *args, **kwargs)
           ^^^^^^^^^^^^^^^^^^^^^^^^^^^
  File "C:\Users\natth\AppData\Roaming\Python\Python312\site-packages\wandb\sdk\wandb_run.py", line 1639, in _console_raw_callback
    self._backend.interface.publish_output_raw(name, data)
  File "C:\Users\natth\AppData\Roaming\Python\Python312\site-packages\wandb\sdk\interface\interface.py", line 762, in publish_output_raw
    self._publish_output_raw(o)
  File "C:\Users\natth\AppData\Roaming\Python\Python312\site-packages\wandb\sdk\interface\interface_shared.py", line 38, in _publish_output_raw
    self._publish(rec)
  File "C:\Users\natth\AppData\Roaming\Python\Python312\site-packages\wandb\sdk\interface\interface_sock.py", line 39, in _publish
    self._sock_client.send_record_publish(record)
  File "C:\Users\natth\AppData\Roaming\Python\Python312\site-packages\wandb\sdk\lib\sock_client.py", line 174, in send_record_publish
    self.send_server_request(server_req)
  File "C:\Users\natth\AppData\Roaming\Python\Python312\site-packages\wandb\sdk\lib\sock_client.py", line 154, in send_server_request
    self._send_message(msg)
  File "C:\Users\natth\AppData\Roaming\Python\Python312\site-packages\wandb\sdk\lib\sock_client.py", line 151, in _send_message
    self._sendall_with_error_handle(header + data)
  File "C:\Users\natth\AppData\Roaming\Python\Python312\site-packages\wandb\sdk\lib\sock_client.py", line 130, in _sendall_with_error_handle
    sent = self._sock.send(data)
           ^^^^^^^^^^^^^^^^^^^^^
ConnectionAbortedError: [WinError 10053] An established connection was aborted by the software in your host machine
2025-05-23 09:13:32,964 ERROR   Thread-38 :43512 [redirect.py:_on_write():664] [no run ID] error in stdout callback
Traceback (most recent call last):
  File "C:\Users\natth\AppData\Roaming\Python\Python312\site-packages\wandb\sdk\lib\redirect.py", line 662, in _on_write
    cb(written_data)
  File "C:\Users\natth\AppData\Roaming\Python\Python312\site-packages\wandb\sdk\wandb_run.py", line 2494, in <lambda>
    lambda data: self._console_raw_callback("stdout", data),
                 ^^^^^^^^^^^^^^^^^^^^^^^^^^^^^^^^^^^^^^^^^^
  File "C:\Users\natth\AppData\Roaming\Python\Python312\site-packages\wandb\sdk\wandb_run.py", line 406, in wrapper
    return func(self, *args, **kwargs)
           ^^^^^^^^^^^^^^^^^^^^^^^^^^^
  File "C:\Users\natth\AppData\Roaming\Python\Python312\site-packages\wandb\sdk\wandb_run.py", line 464, in wrapper_fn
    return func(self, *args, **kwargs)
           ^^^^^^^^^^^^^^^^^^^^^^^^^^^
  File "C:\Users\natth\AppData\Roaming\Python\Python312\site-packages\wandb\sdk\wandb_run.py", line 1639, in _console_raw_callback
    self._backend.interface.publish_output_raw(name, data)
  File "C:\Users\natth\AppData\Roaming\Python\Python312\site-packages\wandb\sdk\interface\interface.py", line 762, in publish_output_raw
    self._publish_output_raw(o)
  File "C:\Users\natth\AppData\Roaming\Python\Python312\site-packages\wandb\sdk\interface\interface_shared.py", line 38, in _publish_output_raw
    self._publish(rec)
  File "C:\Users\natth\AppData\Roaming\Python\Python312\site-packages\wandb\sdk\interface\interface_sock.py", line 39, in _publish
    self._sock_client.send_record_publish(record)
  File "C:\Users\natth\AppData\Roaming\Python\Python312\site-packages\wandb\sdk\lib\sock_client.py", line 174, in send_record_publish
    self.send_server_request(server_req)
  File "C:\Users\natth\AppData\Roaming\Python\Python312\site-packages\wandb\sdk\lib\sock_client.py", line 154, in send_server_request
    self._send_message(msg)
  File "C:\Users\natth\AppData\Roaming\Python\Python312\site-packages\wandb\sdk\lib\sock_client.py", line 151, in _send_message
    self._sendall_with_error_handle(header + data)
  File "C:\Users\natth\AppData\Roaming\Python\Python312\site-packages\wandb\sdk\lib\sock_client.py", line 130, in _sendall_with_error_handle
    sent = self._sock.send(data)
           ^^^^^^^^^^^^^^^^^^^^^
ConnectionAbortedError: [WinError 10053] An established connection was aborted by the software in your host machine
2025-05-23 09:13:33,068 ERROR   Thread-38 :43512 [redirect.py:_on_write():664] [no run ID] error in stdout callback
Traceback (most recent call last):
  File "C:\Users\natth\AppData\Roaming\Python\Python312\site-packages\wandb\sdk\lib\redirect.py", line 662, in _on_write
    cb(written_data)
  File "C:\Users\natth\AppData\Roaming\Python\Python312\site-packages\wandb\sdk\wandb_run.py", line 2494, in <lambda>
    lambda data: self._console_raw_callback("stdout", data),
                 ^^^^^^^^^^^^^^^^^^^^^^^^^^^^^^^^^^^^^^^^^^
  File "C:\Users\natth\AppData\Roaming\Python\Python312\site-packages\wandb\sdk\wandb_run.py", line 406, in wrapper
    return func(self, *args, **kwargs)
           ^^^^^^^^^^^^^^^^^^^^^^^^^^^
  File "C:\Users\natth\AppData\Roaming\Python\Python312\site-packages\wandb\sdk\wandb_run.py", line 464, in wrapper_fn
    return func(self, *args, **kwargs)
           ^^^^^^^^^^^^^^^^^^^^^^^^^^^
  File "C:\Users\natth\AppData\Roaming\Python\Python312\site-packages\wandb\sdk\wandb_run.py", line 1639, in _console_raw_callback
    self._backend.interface.publish_output_raw(name, data)
  File "C:\Users\natth\AppData\Roaming\Python\Python312\site-packages\wandb\sdk\interface\interface.py", line 762, in publish_output_raw
    self._publish_output_raw(o)
  File "C:\Users\natth\AppData\Roaming\Python\Python312\site-packages\wandb\sdk\interface\interface_shared.py", line 38, in _publish_output_raw
    self._publish(rec)
  File "C:\Users\natth\AppData\Roaming\Python\Python312\site-packages\wandb\sdk\interface\interface_sock.py", line 39, in _publish
    self._sock_client.send_record_publish(record)
  File "C:\Users\natth\AppData\Roaming\Python\Python312\site-packages\wandb\sdk\lib\sock_client.py", line 174, in send_record_publish
    self.send_server_request(server_req)
  File "C:\Users\natth\AppData\Roaming\Python\Python312\site-packages\wandb\sdk\lib\sock_client.py", line 154, in send_server_request
    self._send_message(msg)
  File "C:\Users\natth\AppData\Roaming\Python\Python312\site-packages\wandb\sdk\lib\sock_client.py", line 151, in _send_message
    self._sendall_with_error_handle(header + data)
  File "C:\Users\natth\AppData\Roaming\Python\Python312\site-packages\wandb\sdk\lib\sock_client.py", line 130, in _sendall_with_error_handle
    sent = self._sock.send(data)
           ^^^^^^^^^^^^^^^^^^^^^
ConnectionAbortedError: [WinError 10053] An established connection was aborted by the software in your host machine
2025-05-23 09:13:33,172 ERROR   Thread-38 :43512 [redirect.py:_on_write():664] [no run ID] error in stdout callback
Traceback (most recent call last):
  File "C:\Users\natth\AppData\Roaming\Python\Python312\site-packages\wandb\sdk\lib\redirect.py", line 662, in _on_write
    cb(written_data)
  File "C:\Users\natth\AppData\Roaming\Python\Python312\site-packages\wandb\sdk\wandb_run.py", line 2494, in <lambda>
    lambda data: self._console_raw_callback("stdout", data),
                 ^^^^^^^^^^^^^^^^^^^^^^^^^^^^^^^^^^^^^^^^^^
  File "C:\Users\natth\AppData\Roaming\Python\Python312\site-packages\wandb\sdk\wandb_run.py", line 406, in wrapper
    return func(self, *args, **kwargs)
           ^^^^^^^^^^^^^^^^^^^^^^^^^^^
  File "C:\Users\natth\AppData\Roaming\Python\Python312\site-packages\wandb\sdk\wandb_run.py", line 464, in wrapper_fn
    return func(self, *args, **kwargs)
           ^^^^^^^^^^^^^^^^^^^^^^^^^^^
  File "C:\Users\natth\AppData\Roaming\Python\Python312\site-packages\wandb\sdk\wandb_run.py", line 1639, in _console_raw_callback
    self._backend.interface.publish_output_raw(name, data)
  File "C:\Users\natth\AppData\Roaming\Python\Python312\site-packages\wandb\sdk\interface\interface.py", line 762, in publish_output_raw
    self._publish_output_raw(o)
  File "C:\Users\natth\AppData\Roaming\Python\Python312\site-packages\wandb\sdk\interface\interface_shared.py", line 38, in _publish_output_raw
    self._publish(rec)
  File "C:\Users\natth\AppData\Roaming\Python\Python312\site-packages\wandb\sdk\interface\interface_sock.py", line 39, in _publish
    self._sock_client.send_record_publish(record)
  File "C:\Users\natth\AppData\Roaming\Python\Python312\site-packages\wandb\sdk\lib\sock_client.py", line 174, in send_record_publish
    self.send_server_request(server_req)
  File "C:\Users\natth\AppData\Roaming\Python\Python312\site-packages\wandb\sdk\lib\sock_client.py", line 154, in send_server_request
    self._send_message(msg)
  File "C:\Users\natth\AppData\Roaming\Python\Python312\site-packages\wandb\sdk\lib\sock_client.py", line 151, in _send_message
    self._sendall_with_error_handle(header + data)
  File "C:\Users\natth\AppData\Roaming\Python\Python312\site-packages\wandb\sdk\lib\sock_client.py", line 130, in _sendall_with_error_handle
    sent = self._sock.send(data)
           ^^^^^^^^^^^^^^^^^^^^^
ConnectionAbortedError: [WinError 10053] An established connection was aborted by the software in your host machine
2025-05-23 09:13:33,277 ERROR   Thread-38 :43512 [redirect.py:_on_write():664] [no run ID] error in stdout callback
Traceback (most recent call last):
  File "C:\Users\natth\AppData\Roaming\Python\Python312\site-packages\wandb\sdk\lib\redirect.py", line 662, in _on_write
    cb(written_data)
  File "C:\Users\natth\AppData\Roaming\Python\Python312\site-packages\wandb\sdk\wandb_run.py", line 2494, in <lambda>
    lambda data: self._console_raw_callback("stdout", data),
                 ^^^^^^^^^^^^^^^^^^^^^^^^^^^^^^^^^^^^^^^^^^
  File "C:\Users\natth\AppData\Roaming\Python\Python312\site-packages\wandb\sdk\wandb_run.py", line 406, in wrapper
    return func(self, *args, **kwargs)
           ^^^^^^^^^^^^^^^^^^^^^^^^^^^
  File "C:\Users\natth\AppData\Roaming\Python\Python312\site-packages\wandb\sdk\wandb_run.py", line 464, in wrapper_fn
    return func(self, *args, **kwargs)
           ^^^^^^^^^^^^^^^^^^^^^^^^^^^
  File "C:\Users\natth\AppData\Roaming\Python\Python312\site-packages\wandb\sdk\wandb_run.py", line 1639, in _console_raw_callback
    self._backend.interface.publish_output_raw(name, data)
  File "C:\Users\natth\AppData\Roaming\Python\Python312\site-packages\wandb\sdk\interface\interface.py", line 762, in publish_output_raw
    self._publish_output_raw(o)
  File "C:\Users\natth\AppData\Roaming\Python\Python312\site-packages\wandb\sdk\interface\interface_shared.py", line 38, in _publish_output_raw
    self._publish(rec)
  File "C:\Users\natth\AppData\Roaming\Python\Python312\site-packages\wandb\sdk\interface\interface_sock.py", line 39, in _publish
    self._sock_client.send_record_publish(record)
  File "C:\Users\natth\AppData\Roaming\Python\Python312\site-packages\wandb\sdk\lib\sock_client.py", line 174, in send_record_publish
    self.send_server_request(server_req)
  File "C:\Users\natth\AppData\Roaming\Python\Python312\site-packages\wandb\sdk\lib\sock_client.py", line 154, in send_server_request
    self._send_message(msg)
  File "C:\Users\natth\AppData\Roaming\Python\Python312\site-packages\wandb\sdk\lib\sock_client.py", line 151, in _send_message
    self._sendall_with_error_handle(header + data)
  File "C:\Users\natth\AppData\Roaming\Python\Python312\site-packages\wandb\sdk\lib\sock_client.py", line 130, in _sendall_with_error_handle
    sent = self._sock.send(data)
           ^^^^^^^^^^^^^^^^^^^^^
ConnectionAbortedError: [WinError 10053] An established connection was aborted by the software in your host machine
2025-05-23 09:13:33,382 ERROR   Thread-38 :43512 [redirect.py:_on_write():664] [no run ID] error in stdout callback
Traceback (most recent call last):
  File "C:\Users\natth\AppData\Roaming\Python\Python312\site-packages\wandb\sdk\lib\redirect.py", line 662, in _on_write
    cb(written_data)
  File "C:\Users\natth\AppData\Roaming\Python\Python312\site-packages\wandb\sdk\wandb_run.py", line 2494, in <lambda>
    lambda data: self._console_raw_callback("stdout", data),
                 ^^^^^^^^^^^^^^^^^^^^^^^^^^^^^^^^^^^^^^^^^^
  File "C:\Users\natth\AppData\Roaming\Python\Python312\site-packages\wandb\sdk\wandb_run.py", line 406, in wrapper
    return func(self, *args, **kwargs)
           ^^^^^^^^^^^^^^^^^^^^^^^^^^^
  File "C:\Users\natth\AppData\Roaming\Python\Python312\site-packages\wandb\sdk\wandb_run.py", line 464, in wrapper_fn
    return func(self, *args, **kwargs)
           ^^^^^^^^^^^^^^^^^^^^^^^^^^^
  File "C:\Users\natth\AppData\Roaming\Python\Python312\site-packages\wandb\sdk\wandb_run.py", line 1639, in _console_raw_callback
    self._backend.interface.publish_output_raw(name, data)
  File "C:\Users\natth\AppData\Roaming\Python\Python312\site-packages\wandb\sdk\interface\interface.py", line 762, in publish_output_raw
    self._publish_output_raw(o)
  File "C:\Users\natth\AppData\Roaming\Python\Python312\site-packages\wandb\sdk\interface\interface_shared.py", line 38, in _publish_output_raw
    self._publish(rec)
  File "C:\Users\natth\AppData\Roaming\Python\Python312\site-packages\wandb\sdk\interface\interface_sock.py", line 39, in _publish
    self._sock_client.send_record_publish(record)
  File "C:\Users\natth\AppData\Roaming\Python\Python312\site-packages\wandb\sdk\lib\sock_client.py", line 174, in send_record_publish
    self.send_server_request(server_req)
  File "C:\Users\natth\AppData\Roaming\Python\Python312\site-packages\wandb\sdk\lib\sock_client.py", line 154, in send_server_request
    self._send_message(msg)
  File "C:\Users\natth\AppData\Roaming\Python\Python312\site-packages\wandb\sdk\lib\sock_client.py", line 151, in _send_message
    self._sendall_with_error_handle(header + data)
  File "C:\Users\natth\AppData\Roaming\Python\Python312\site-packages\wandb\sdk\lib\sock_client.py", line 130, in _sendall_with_error_handle
    sent = self._sock.send(data)
           ^^^^^^^^^^^^^^^^^^^^^
ConnectionAbortedError: [WinError 10053] An established connection was aborted by the software in your host machine
2025-05-23 09:13:33,488 ERROR   Thread-38 :43512 [redirect.py:_on_write():664] [no run ID] error in stdout callback
Traceback (most recent call last):
  File "C:\Users\natth\AppData\Roaming\Python\Python312\site-packages\wandb\sdk\lib\redirect.py", line 662, in _on_write
    cb(written_data)
  File "C:\Users\natth\AppData\Roaming\Python\Python312\site-packages\wandb\sdk\wandb_run.py", line 2494, in <lambda>
    lambda data: self._console_raw_callback("stdout", data),
                 ^^^^^^^^^^^^^^^^^^^^^^^^^^^^^^^^^^^^^^^^^^
  File "C:\Users\natth\AppData\Roaming\Python\Python312\site-packages\wandb\sdk\wandb_run.py", line 406, in wrapper
    return func(self, *args, **kwargs)
           ^^^^^^^^^^^^^^^^^^^^^^^^^^^
  File "C:\Users\natth\AppData\Roaming\Python\Python312\site-packages\wandb\sdk\wandb_run.py", line 464, in wrapper_fn
    return func(self, *args, **kwargs)
           ^^^^^^^^^^^^^^^^^^^^^^^^^^^
  File "C:\Users\natth\AppData\Roaming\Python\Python312\site-packages\wandb\sdk\wandb_run.py", line 1639, in _console_raw_callback
    self._backend.interface.publish_output_raw(name, data)
  File "C:\Users\natth\AppData\Roaming\Python\Python312\site-packages\wandb\sdk\interface\interface.py", line 762, in publish_output_raw
    self._publish_output_raw(o)
  File "C:\Users\natth\AppData\Roaming\Python\Python312\site-packages\wandb\sdk\interface\interface_shared.py", line 38, in _publish_output_raw
    self._publish(rec)
  File "C:\Users\natth\AppData\Roaming\Python\Python312\site-packages\wandb\sdk\interface\interface_sock.py", line 39, in _publish
    self._sock_client.send_record_publish(record)
  File "C:\Users\natth\AppData\Roaming\Python\Python312\site-packages\wandb\sdk\lib\sock_client.py", line 174, in send_record_publish
    self.send_server_request(server_req)
  File "C:\Users\natth\AppData\Roaming\Python\Python312\site-packages\wandb\sdk\lib\sock_client.py", line 154, in send_server_request
    self._send_message(msg)
  File "C:\Users\natth\AppData\Roaming\Python\Python312\site-packages\wandb\sdk\lib\sock_client.py", line 151, in _send_message
    self._sendall_with_error_handle(header + data)
  File "C:\Users\natth\AppData\Roaming\Python\Python312\site-packages\wandb\sdk\lib\sock_client.py", line 130, in _sendall_with_error_handle
    sent = self._sock.send(data)
           ^^^^^^^^^^^^^^^^^^^^^
ConnectionAbortedError: [WinError 10053] An established connection was aborted by the software in your host machine
2025-05-23 09:13:33,591 ERROR   Thread-38 :43512 [redirect.py:_on_write():664] [no run ID] error in stdout callback
Traceback (most recent call last):
  File "C:\Users\natth\AppData\Roaming\Python\Python312\site-packages\wandb\sdk\lib\redirect.py", line 662, in _on_write
    cb(written_data)
  File "C:\Users\natth\AppData\Roaming\Python\Python312\site-packages\wandb\sdk\wandb_run.py", line 2494, in <lambda>
    lambda data: self._console_raw_callback("stdout", data),
                 ^^^^^^^^^^^^^^^^^^^^^^^^^^^^^^^^^^^^^^^^^^
  File "C:\Users\natth\AppData\Roaming\Python\Python312\site-packages\wandb\sdk\wandb_run.py", line 406, in wrapper
    return func(self, *args, **kwargs)
           ^^^^^^^^^^^^^^^^^^^^^^^^^^^
  File "C:\Users\natth\AppData\Roaming\Python\Python312\site-packages\wandb\sdk\wandb_run.py", line 464, in wrapper_fn
    return func(self, *args, **kwargs)
           ^^^^^^^^^^^^^^^^^^^^^^^^^^^
  File "C:\Users\natth\AppData\Roaming\Python\Python312\site-packages\wandb\sdk\wandb_run.py", line 1639, in _console_raw_callback
    self._backend.interface.publish_output_raw(name, data)
  File "C:\Users\natth\AppData\Roaming\Python\Python312\site-packages\wandb\sdk\interface\interface.py", line 762, in publish_output_raw
    self._publish_output_raw(o)
  File "C:\Users\natth\AppData\Roaming\Python\Python312\site-packages\wandb\sdk\interface\interface_shared.py", line 38, in _publish_output_raw
    self._publish(rec)
  File "C:\Users\natth\AppData\Roaming\Python\Python312\site-packages\wandb\sdk\interface\interface_sock.py", line 39, in _publish
    self._sock_client.send_record_publish(record)
  File "C:\Users\natth\AppData\Roaming\Python\Python312\site-packages\wandb\sdk\lib\sock_client.py", line 174, in send_record_publish
    self.send_server_request(server_req)
  File "C:\Users\natth\AppData\Roaming\Python\Python312\site-packages\wandb\sdk\lib\sock_client.py", line 154, in send_server_request
    self._send_message(msg)
  File "C:\Users\natth\AppData\Roaming\Python\Python312\site-packages\wandb\sdk\lib\sock_client.py", line 151, in _send_message
    self._sendall_with_error_handle(header + data)
  File "C:\Users\natth\AppData\Roaming\Python\Python312\site-packages\wandb\sdk\lib\sock_client.py", line 130, in _sendall_with_error_handle
    sent = self._sock.send(data)
           ^^^^^^^^^^^^^^^^^^^^^
ConnectionAbortedError: [WinError 10053] An established connection was aborted by the software in your host machine
2025-05-23 09:13:33,695 ERROR   Thread-38 :43512 [redirect.py:_on_write():664] [no run ID] error in stdout callback
Traceback (most recent call last):
  File "C:\Users\natth\AppData\Roaming\Python\Python312\site-packages\wandb\sdk\lib\redirect.py", line 662, in _on_write
    cb(written_data)
  File "C:\Users\natth\AppData\Roaming\Python\Python312\site-packages\wandb\sdk\wandb_run.py", line 2494, in <lambda>
    lambda data: self._console_raw_callback("stdout", data),
                 ^^^^^^^^^^^^^^^^^^^^^^^^^^^^^^^^^^^^^^^^^^
  File "C:\Users\natth\AppData\Roaming\Python\Python312\site-packages\wandb\sdk\wandb_run.py", line 406, in wrapper
    return func(self, *args, **kwargs)
           ^^^^^^^^^^^^^^^^^^^^^^^^^^^
  File "C:\Users\natth\AppData\Roaming\Python\Python312\site-packages\wandb\sdk\wandb_run.py", line 464, in wrapper_fn
    return func(self, *args, **kwargs)
           ^^^^^^^^^^^^^^^^^^^^^^^^^^^
  File "C:\Users\natth\AppData\Roaming\Python\Python312\site-packages\wandb\sdk\wandb_run.py", line 1639, in _console_raw_callback
    self._backend.interface.publish_output_raw(name, data)
  File "C:\Users\natth\AppData\Roaming\Python\Python312\site-packages\wandb\sdk\interface\interface.py", line 762, in publish_output_raw
    self._publish_output_raw(o)
  File "C:\Users\natth\AppData\Roaming\Python\Python312\site-packages\wandb\sdk\interface\interface_shared.py", line 38, in _publish_output_raw
    self._publish(rec)
  File "C:\Users\natth\AppData\Roaming\Python\Python312\site-packages\wandb\sdk\interface\interface_sock.py", line 39, in _publish
    self._sock_client.send_record_publish(record)
  File "C:\Users\natth\AppData\Roaming\Python\Python312\site-packages\wandb\sdk\lib\sock_client.py", line 174, in send_record_publish
    self.send_server_request(server_req)
  File "C:\Users\natth\AppData\Roaming\Python\Python312\site-packages\wandb\sdk\lib\sock_client.py", line 154, in send_server_request
    self._send_message(msg)
  File "C:\Users\natth\AppData\Roaming\Python\Python312\site-packages\wandb\sdk\lib\sock_client.py", line 151, in _send_message
    self._sendall_with_error_handle(header + data)
  File "C:\Users\natth\AppData\Roaming\Python\Python312\site-packages\wandb\sdk\lib\sock_client.py", line 130, in _sendall_with_error_handle
    sent = self._sock.send(data)
           ^^^^^^^^^^^^^^^^^^^^^
ConnectionAbortedError: [WinError 10053] An established connection was aborted by the software in your host machine
2025-05-23 09:13:33,801 ERROR   Thread-38 :43512 [redirect.py:_on_write():664] [no run ID] error in stdout callback
Traceback (most recent call last):
  File "C:\Users\natth\AppData\Roaming\Python\Python312\site-packages\wandb\sdk\lib\redirect.py", line 662, in _on_write
    cb(written_data)
  File "C:\Users\natth\AppData\Roaming\Python\Python312\site-packages\wandb\sdk\wandb_run.py", line 2494, in <lambda>
    lambda data: self._console_raw_callback("stdout", data),
                 ^^^^^^^^^^^^^^^^^^^^^^^^^^^^^^^^^^^^^^^^^^
  File "C:\Users\natth\AppData\Roaming\Python\Python312\site-packages\wandb\sdk\wandb_run.py", line 406, in wrapper
    return func(self, *args, **kwargs)
           ^^^^^^^^^^^^^^^^^^^^^^^^^^^
  File "C:\Users\natth\AppData\Roaming\Python\Python312\site-packages\wandb\sdk\wandb_run.py", line 464, in wrapper_fn
    return func(self, *args, **kwargs)
           ^^^^^^^^^^^^^^^^^^^^^^^^^^^
  File "C:\Users\natth\AppData\Roaming\Python\Python312\site-packages\wandb\sdk\wandb_run.py", line 1639, in _console_raw_callback
    self._backend.interface.publish_output_raw(name, data)
  File "C:\Users\natth\AppData\Roaming\Python\Python312\site-packages\wandb\sdk\interface\interface.py", line 762, in publish_output_raw
    self._publish_output_raw(o)
  File "C:\Users\natth\AppData\Roaming\Python\Python312\site-packages\wandb\sdk\interface\interface_shared.py", line 38, in _publish_output_raw
    self._publish(rec)
  File "C:\Users\natth\AppData\Roaming\Python\Python312\site-packages\wandb\sdk\interface\interface_sock.py", line 39, in _publish
    self._sock_client.send_record_publish(record)
  File "C:\Users\natth\AppData\Roaming\Python\Python312\site-packages\wandb\sdk\lib\sock_client.py", line 174, in send_record_publish
    self.send_server_request(server_req)
  File "C:\Users\natth\AppData\Roaming\Python\Python312\site-packages\wandb\sdk\lib\sock_client.py", line 154, in send_server_request
    self._send_message(msg)
  File "C:\Users\natth\AppData\Roaming\Python\Python312\site-packages\wandb\sdk\lib\sock_client.py", line 151, in _send_message
    self._sendall_with_error_handle(header + data)
  File "C:\Users\natth\AppData\Roaming\Python\Python312\site-packages\wandb\sdk\lib\sock_client.py", line 130, in _sendall_with_error_handle
    sent = self._sock.send(data)
           ^^^^^^^^^^^^^^^^^^^^^
ConnectionAbortedError: [WinError 10053] An established connection was aborted by the software in your host machine
2025-05-23 09:13:33,908 ERROR   Thread-38 :43512 [redirect.py:_on_write():664] [no run ID] error in stdout callback
Traceback (most recent call last):
  File "C:\Users\natth\AppData\Roaming\Python\Python312\site-packages\wandb\sdk\lib\redirect.py", line 662, in _on_write
    cb(written_data)
  File "C:\Users\natth\AppData\Roaming\Python\Python312\site-packages\wandb\sdk\wandb_run.py", line 2494, in <lambda>
    lambda data: self._console_raw_callback("stdout", data),
                 ^^^^^^^^^^^^^^^^^^^^^^^^^^^^^^^^^^^^^^^^^^
  File "C:\Users\natth\AppData\Roaming\Python\Python312\site-packages\wandb\sdk\wandb_run.py", line 406, in wrapper
    return func(self, *args, **kwargs)
           ^^^^^^^^^^^^^^^^^^^^^^^^^^^
  File "C:\Users\natth\AppData\Roaming\Python\Python312\site-packages\wandb\sdk\wandb_run.py", line 464, in wrapper_fn
    return func(self, *args, **kwargs)
           ^^^^^^^^^^^^^^^^^^^^^^^^^^^
  File "C:\Users\natth\AppData\Roaming\Python\Python312\site-packages\wandb\sdk\wandb_run.py", line 1639, in _console_raw_callback
    self._backend.interface.publish_output_raw(name, data)
  File "C:\Users\natth\AppData\Roaming\Python\Python312\site-packages\wandb\sdk\interface\interface.py", line 762, in publish_output_raw
    self._publish_output_raw(o)
  File "C:\Users\natth\AppData\Roaming\Python\Python312\site-packages\wandb\sdk\interface\interface_shared.py", line 38, in _publish_output_raw
    self._publish(rec)
  File "C:\Users\natth\AppData\Roaming\Python\Python312\site-packages\wandb\sdk\interface\interface_sock.py", line 39, in _publish
    self._sock_client.send_record_publish(record)
  File "C:\Users\natth\AppData\Roaming\Python\Python312\site-packages\wandb\sdk\lib\sock_client.py", line 174, in send_record_publish
    self.send_server_request(server_req)
  File "C:\Users\natth\AppData\Roaming\Python\Python312\site-packages\wandb\sdk\lib\sock_client.py", line 154, in send_server_request
    self._send_message(msg)
  File "C:\Users\natth\AppData\Roaming\Python\Python312\site-packages\wandb\sdk\lib\sock_client.py", line 151, in _send_message
    self._sendall_with_error_handle(header + data)
  File "C:\Users\natth\AppData\Roaming\Python\Python312\site-packages\wandb\sdk\lib\sock_client.py", line 130, in _sendall_with_error_handle
    sent = self._sock.send(data)
           ^^^^^^^^^^^^^^^^^^^^^
ConnectionAbortedError: [WinError 10053] An established connection was aborted by the software in your host machine
2025-05-23 09:13:34,016 ERROR   Thread-38 :43512 [redirect.py:_on_write():664] [no run ID] error in stdout callback
Traceback (most recent call last):
  File "C:\Users\natth\AppData\Roaming\Python\Python312\site-packages\wandb\sdk\lib\redirect.py", line 662, in _on_write
    cb(written_data)
  File "C:\Users\natth\AppData\Roaming\Python\Python312\site-packages\wandb\sdk\wandb_run.py", line 2494, in <lambda>
    lambda data: self._console_raw_callback("stdout", data),
                 ^^^^^^^^^^^^^^^^^^^^^^^^^^^^^^^^^^^^^^^^^^
  File "C:\Users\natth\AppData\Roaming\Python\Python312\site-packages\wandb\sdk\wandb_run.py", line 406, in wrapper
    return func(self, *args, **kwargs)
           ^^^^^^^^^^^^^^^^^^^^^^^^^^^
  File "C:\Users\natth\AppData\Roaming\Python\Python312\site-packages\wandb\sdk\wandb_run.py", line 464, in wrapper_fn
    return func(self, *args, **kwargs)
           ^^^^^^^^^^^^^^^^^^^^^^^^^^^
  File "C:\Users\natth\AppData\Roaming\Python\Python312\site-packages\wandb\sdk\wandb_run.py", line 1639, in _console_raw_callback
    self._backend.interface.publish_output_raw(name, data)
  File "C:\Users\natth\AppData\Roaming\Python\Python312\site-packages\wandb\sdk\interface\interface.py", line 762, in publish_output_raw
    self._publish_output_raw(o)
  File "C:\Users\natth\AppData\Roaming\Python\Python312\site-packages\wandb\sdk\interface\interface_shared.py", line 38, in _publish_output_raw
    self._publish(rec)
  File "C:\Users\natth\AppData\Roaming\Python\Python312\site-packages\wandb\sdk\interface\interface_sock.py", line 39, in _publish
    self._sock_client.send_record_publish(record)
  File "C:\Users\natth\AppData\Roaming\Python\Python312\site-packages\wandb\sdk\lib\sock_client.py", line 174, in send_record_publish
    self.send_server_request(server_req)
  File "C:\Users\natth\AppData\Roaming\Python\Python312\site-packages\wandb\sdk\lib\sock_client.py", line 154, in send_server_request
    self._send_message(msg)
  File "C:\Users\natth\AppData\Roaming\Python\Python312\site-packages\wandb\sdk\lib\sock_client.py", line 151, in _send_message
    self._sendall_with_error_handle(header + data)
  File "C:\Users\natth\AppData\Roaming\Python\Python312\site-packages\wandb\sdk\lib\sock_client.py", line 130, in _sendall_with_error_handle
    sent = self._sock.send(data)
           ^^^^^^^^^^^^^^^^^^^^^
ConnectionAbortedError: [WinError 10053] An established connection was aborted by the software in your host machine
2025-05-23 09:13:34,121 ERROR   Thread-38 :43512 [redirect.py:_on_write():664] [no run ID] error in stdout callback
Traceback (most recent call last):
  File "C:\Users\natth\AppData\Roaming\Python\Python312\site-packages\wandb\sdk\lib\redirect.py", line 662, in _on_write
    cb(written_data)
  File "C:\Users\natth\AppData\Roaming\Python\Python312\site-packages\wandb\sdk\wandb_run.py", line 2494, in <lambda>
    lambda data: self._console_raw_callback("stdout", data),
                 ^^^^^^^^^^^^^^^^^^^^^^^^^^^^^^^^^^^^^^^^^^
  File "C:\Users\natth\AppData\Roaming\Python\Python312\site-packages\wandb\sdk\wandb_run.py", line 406, in wrapper
    return func(self, *args, **kwargs)
           ^^^^^^^^^^^^^^^^^^^^^^^^^^^
  File "C:\Users\natth\AppData\Roaming\Python\Python312\site-packages\wandb\sdk\wandb_run.py", line 464, in wrapper_fn
    return func(self, *args, **kwargs)
           ^^^^^^^^^^^^^^^^^^^^^^^^^^^
  File "C:\Users\natth\AppData\Roaming\Python\Python312\site-packages\wandb\sdk\wandb_run.py", line 1639, in _console_raw_callback
    self._backend.interface.publish_output_raw(name, data)
  File "C:\Users\natth\AppData\Roaming\Python\Python312\site-packages\wandb\sdk\interface\interface.py", line 762, in publish_output_raw
    self._publish_output_raw(o)
  File "C:\Users\natth\AppData\Roaming\Python\Python312\site-packages\wandb\sdk\interface\interface_shared.py", line 38, in _publish_output_raw
    self._publish(rec)
  File "C:\Users\natth\AppData\Roaming\Python\Python312\site-packages\wandb\sdk\interface\interface_sock.py", line 39, in _publish
    self._sock_client.send_record_publish(record)
  File "C:\Users\natth\AppData\Roaming\Python\Python312\site-packages\wandb\sdk\lib\sock_client.py", line 174, in send_record_publish
    self.send_server_request(server_req)
  File "C:\Users\natth\AppData\Roaming\Python\Python312\site-packages\wandb\sdk\lib\sock_client.py", line 154, in send_server_request
    self._send_message(msg)
  File "C:\Users\natth\AppData\Roaming\Python\Python312\site-packages\wandb\sdk\lib\sock_client.py", line 151, in _send_message
    self._sendall_with_error_handle(header + data)
  File "C:\Users\natth\AppData\Roaming\Python\Python312\site-packages\wandb\sdk\lib\sock_client.py", line 130, in _sendall_with_error_handle
    sent = self._sock.send(data)
           ^^^^^^^^^^^^^^^^^^^^^
ConnectionAbortedError: [WinError 10053] An established connection was aborted by the software in your host machine
2025-05-23 09:13:34,257 ERROR   Thread-38 :43512 [redirect.py:_on_write():664] [no run ID] error in stdout callback
Traceback (most recent call last):
  File "C:\Users\natth\AppData\Roaming\Python\Python312\site-packages\wandb\sdk\lib\redirect.py", line 662, in _on_write
    cb(written_data)
  File "C:\Users\natth\AppData\Roaming\Python\Python312\site-packages\wandb\sdk\wandb_run.py", line 2494, in <lambda>
    lambda data: self._console_raw_callback("stdout", data),
                 ^^^^^^^^^^^^^^^^^^^^^^^^^^^^^^^^^^^^^^^^^^
  File "C:\Users\natth\AppData\Roaming\Python\Python312\site-packages\wandb\sdk\wandb_run.py", line 406, in wrapper
    return func(self, *args, **kwargs)
           ^^^^^^^^^^^^^^^^^^^^^^^^^^^
  File "C:\Users\natth\AppData\Roaming\Python\Python312\site-packages\wandb\sdk\wandb_run.py", line 464, in wrapper_fn
    return func(self, *args, **kwargs)
           ^^^^^^^^^^^^^^^^^^^^^^^^^^^
  File "C:\Users\natth\AppData\Roaming\Python\Python312\site-packages\wandb\sdk\wandb_run.py", line 1639, in _console_raw_callback
    self._backend.interface.publish_output_raw(name, data)
  File "C:\Users\natth\AppData\Roaming\Python\Python312\site-packages\wandb\sdk\interface\interface.py", line 762, in publish_output_raw
    self._publish_output_raw(o)
  File "C:\Users\natth\AppData\Roaming\Python\Python312\site-packages\wandb\sdk\interface\interface_shared.py", line 38, in _publish_output_raw
    self._publish(rec)
  File "C:\Users\natth\AppData\Roaming\Python\Python312\site-packages\wandb\sdk\interface\interface_sock.py", line 39, in _publish
    self._sock_client.send_record_publish(record)
  File "C:\Users\natth\AppData\Roaming\Python\Python312\site-packages\wandb\sdk\lib\sock_client.py", line 174, in send_record_publish
    self.send_server_request(server_req)
  File "C:\Users\natth\AppData\Roaming\Python\Python312\site-packages\wandb\sdk\lib\sock_client.py", line 154, in send_server_request
    self._send_message(msg)
  File "C:\Users\natth\AppData\Roaming\Python\Python312\site-packages\wandb\sdk\lib\sock_client.py", line 151, in _send_message
    self._sendall_with_error_handle(header + data)
  File "C:\Users\natth\AppData\Roaming\Python\Python312\site-packages\wandb\sdk\lib\sock_client.py", line 130, in _sendall_with_error_handle
    sent = self._sock.send(data)
           ^^^^^^^^^^^^^^^^^^^^^
ConnectionAbortedError: [WinError 10053] An established connection was aborted by the software in your host machine
2025-05-23 09:13:34,362 ERROR   Thread-38 :43512 [redirect.py:_on_write():664] [no run ID] error in stdout callback
Traceback (most recent call last):
  File "C:\Users\natth\AppData\Roaming\Python\Python312\site-packages\wandb\sdk\lib\redirect.py", line 662, in _on_write
    cb(written_data)
  File "C:\Users\natth\AppData\Roaming\Python\Python312\site-packages\wandb\sdk\wandb_run.py", line 2494, in <lambda>
    lambda data: self._console_raw_callback("stdout", data),
                 ^^^^^^^^^^^^^^^^^^^^^^^^^^^^^^^^^^^^^^^^^^
  File "C:\Users\natth\AppData\Roaming\Python\Python312\site-packages\wandb\sdk\wandb_run.py", line 406, in wrapper
    return func(self, *args, **kwargs)
           ^^^^^^^^^^^^^^^^^^^^^^^^^^^
  File "C:\Users\natth\AppData\Roaming\Python\Python312\site-packages\wandb\sdk\wandb_run.py", line 464, in wrapper_fn
    return func(self, *args, **kwargs)
           ^^^^^^^^^^^^^^^^^^^^^^^^^^^
  File "C:\Users\natth\AppData\Roaming\Python\Python312\site-packages\wandb\sdk\wandb_run.py", line 1639, in _console_raw_callback
    self._backend.interface.publish_output_raw(name, data)
  File "C:\Users\natth\AppData\Roaming\Python\Python312\site-packages\wandb\sdk\interface\interface.py", line 762, in publish_output_raw
    self._publish_output_raw(o)
  File "C:\Users\natth\AppData\Roaming\Python\Python312\site-packages\wandb\sdk\interface\interface_shared.py", line 38, in _publish_output_raw
    self._publish(rec)
  File "C:\Users\natth\AppData\Roaming\Python\Python312\site-packages\wandb\sdk\interface\interface_sock.py", line 39, in _publish
    self._sock_client.send_record_publish(record)
  File "C:\Users\natth\AppData\Roaming\Python\Python312\site-packages\wandb\sdk\lib\sock_client.py", line 174, in send_record_publish
    self.send_server_request(server_req)
  File "C:\Users\natth\AppData\Roaming\Python\Python312\site-packages\wandb\sdk\lib\sock_client.py", line 154, in send_server_request
    self._send_message(msg)
  File "C:\Users\natth\AppData\Roaming\Python\Python312\site-packages\wandb\sdk\lib\sock_client.py", line 151, in _send_message
    self._sendall_with_error_handle(header + data)
  File "C:\Users\natth\AppData\Roaming\Python\Python312\site-packages\wandb\sdk\lib\sock_client.py", line 130, in _sendall_with_error_handle
    sent = self._sock.send(data)
           ^^^^^^^^^^^^^^^^^^^^^
ConnectionAbortedError: [WinError 10053] An established connection was aborted by the software in your host machine
2025-05-23 09:13:34,476 ERROR   Thread-38 :43512 [redirect.py:_on_write():664] [no run ID] error in stdout callback
Traceback (most recent call last):
  File "C:\Users\natth\AppData\Roaming\Python\Python312\site-packages\wandb\sdk\lib\redirect.py", line 662, in _on_write
    cb(written_data)
  File "C:\Users\natth\AppData\Roaming\Python\Python312\site-packages\wandb\sdk\wandb_run.py", line 2494, in <lambda>
    lambda data: self._console_raw_callback("stdout", data),
                 ^^^^^^^^^^^^^^^^^^^^^^^^^^^^^^^^^^^^^^^^^^
  File "C:\Users\natth\AppData\Roaming\Python\Python312\site-packages\wandb\sdk\wandb_run.py", line 406, in wrapper
    return func(self, *args, **kwargs)
           ^^^^^^^^^^^^^^^^^^^^^^^^^^^
  File "C:\Users\natth\AppData\Roaming\Python\Python312\site-packages\wandb\sdk\wandb_run.py", line 464, in wrapper_fn
    return func(self, *args, **kwargs)
           ^^^^^^^^^^^^^^^^^^^^^^^^^^^
  File "C:\Users\natth\AppData\Roaming\Python\Python312\site-packages\wandb\sdk\wandb_run.py", line 1639, in _console_raw_callback
    self._backend.interface.publish_output_raw(name, data)
  File "C:\Users\natth\AppData\Roaming\Python\Python312\site-packages\wandb\sdk\interface\interface.py", line 762, in publish_output_raw
    self._publish_output_raw(o)
  File "C:\Users\natth\AppData\Roaming\Python\Python312\site-packages\wandb\sdk\interface\interface_shared.py", line 38, in _publish_output_raw
    self._publish(rec)
  File "C:\Users\natth\AppData\Roaming\Python\Python312\site-packages\wandb\sdk\interface\interface_sock.py", line 39, in _publish
    self._sock_client.send_record_publish(record)
  File "C:\Users\natth\AppData\Roaming\Python\Python312\site-packages\wandb\sdk\lib\sock_client.py", line 174, in send_record_publish
    self.send_server_request(server_req)
  File "C:\Users\natth\AppData\Roaming\Python\Python312\site-packages\wandb\sdk\lib\sock_client.py", line 154, in send_server_request
    self._send_message(msg)
  File "C:\Users\natth\AppData\Roaming\Python\Python312\site-packages\wandb\sdk\lib\sock_client.py", line 151, in _send_message
    self._sendall_with_error_handle(header + data)
  File "C:\Users\natth\AppData\Roaming\Python\Python312\site-packages\wandb\sdk\lib\sock_client.py", line 130, in _sendall_with_error_handle
    sent = self._sock.send(data)
           ^^^^^^^^^^^^^^^^^^^^^
ConnectionAbortedError: [WinError 10053] An established connection was aborted by the software in your host machine
2025-05-23 09:13:34,633 ERROR   Thread-38 :43512 [redirect.py:_on_write():664] [no run ID] error in stdout callback
Traceback (most recent call last):
  File "C:\Users\natth\AppData\Roaming\Python\Python312\site-packages\wandb\sdk\lib\redirect.py", line 662, in _on_write
    cb(written_data)
  File "C:\Users\natth\AppData\Roaming\Python\Python312\site-packages\wandb\sdk\wandb_run.py", line 2494, in <lambda>
    lambda data: self._console_raw_callback("stdout", data),
                 ^^^^^^^^^^^^^^^^^^^^^^^^^^^^^^^^^^^^^^^^^^
  File "C:\Users\natth\AppData\Roaming\Python\Python312\site-packages\wandb\sdk\wandb_run.py", line 406, in wrapper
    return func(self, *args, **kwargs)
           ^^^^^^^^^^^^^^^^^^^^^^^^^^^
  File "C:\Users\natth\AppData\Roaming\Python\Python312\site-packages\wandb\sdk\wandb_run.py", line 464, in wrapper_fn
    return func(self, *args, **kwargs)
           ^^^^^^^^^^^^^^^^^^^^^^^^^^^
  File "C:\Users\natth\AppData\Roaming\Python\Python312\site-packages\wandb\sdk\wandb_run.py", line 1639, in _console_raw_callback
    self._backend.interface.publish_output_raw(name, data)
  File "C:\Users\natth\AppData\Roaming\Python\Python312\site-packages\wandb\sdk\interface\interface.py", line 762, in publish_output_raw
    self._publish_output_raw(o)
  File "C:\Users\natth\AppData\Roaming\Python\Python312\site-packages\wandb\sdk\interface\interface_shared.py", line 38, in _publish_output_raw
    self._publish(rec)
  File "C:\Users\natth\AppData\Roaming\Python\Python312\site-packages\wandb\sdk\interface\interface_sock.py", line 39, in _publish
    self._sock_client.send_record_publish(record)
  File "C:\Users\natth\AppData\Roaming\Python\Python312\site-packages\wandb\sdk\lib\sock_client.py", line 174, in send_record_publish
    self.send_server_request(server_req)
  File "C:\Users\natth\AppData\Roaming\Python\Python312\site-packages\wandb\sdk\lib\sock_client.py", line 154, in send_server_request
    self._send_message(msg)
  File "C:\Users\natth\AppData\Roaming\Python\Python312\site-packages\wandb\sdk\lib\sock_client.py", line 151, in _send_message
    self._sendall_with_error_handle(header + data)
  File "C:\Users\natth\AppData\Roaming\Python\Python312\site-packages\wandb\sdk\lib\sock_client.py", line 130, in _sendall_with_error_handle
    sent = self._sock.send(data)
           ^^^^^^^^^^^^^^^^^^^^^
ConnectionAbortedError: [WinError 10053] An established connection was aborted by the software in your host machine
2025-05-23 09:13:34,634 ERROR   MainThread:43512 [redirect.py:_on_write():664] [no run ID] error in stdout callback
Traceback (most recent call last):
  File "C:\Users\natth\AppData\Roaming\Python\Python312\site-packages\wandb\sdk\lib\redirect.py", line 662, in _on_write
    cb(written_data)
  File "C:\Users\natth\AppData\Roaming\Python\Python312\site-packages\wandb\sdk\wandb_run.py", line 2494, in <lambda>
    lambda data: self._console_raw_callback("stdout", data),
                 ^^^^^^^^^^^^^^^^^^^^^^^^^^^^^^^^^^^^^^^^^^
  File "C:\Users\natth\AppData\Roaming\Python\Python312\site-packages\wandb\sdk\wandb_run.py", line 406, in wrapper
    return func(self, *args, **kwargs)
           ^^^^^^^^^^^^^^^^^^^^^^^^^^^
  File "C:\Users\natth\AppData\Roaming\Python\Python312\site-packages\wandb\sdk\wandb_run.py", line 464, in wrapper_fn
    return func(self, *args, **kwargs)
           ^^^^^^^^^^^^^^^^^^^^^^^^^^^
  File "C:\Users\natth\AppData\Roaming\Python\Python312\site-packages\wandb\sdk\wandb_run.py", line 1639, in _console_raw_callback
    self._backend.interface.publish_output_raw(name, data)
  File "C:\Users\natth\AppData\Roaming\Python\Python312\site-packages\wandb\sdk\interface\interface.py", line 762, in publish_output_raw
    self._publish_output_raw(o)
  File "C:\Users\natth\AppData\Roaming\Python\Python312\site-packages\wandb\sdk\interface\interface_shared.py", line 38, in _publish_output_raw
    self._publish(rec)
  File "C:\Users\natth\AppData\Roaming\Python\Python312\site-packages\wandb\sdk\interface\interface_sock.py", line 39, in _publish
    self._sock_client.send_record_publish(record)
  File "C:\Users\natth\AppData\Roaming\Python\Python312\site-packages\wandb\sdk\lib\sock_client.py", line 174, in send_record_publish
    self.send_server_request(server_req)
  File "C:\Users\natth\AppData\Roaming\Python\Python312\site-packages\wandb\sdk\lib\sock_client.py", line 154, in send_server_request
    self._send_message(msg)
  File "C:\Users\natth\AppData\Roaming\Python\Python312\site-packages\wandb\sdk\lib\sock_client.py", line 151, in _send_message
    self._sendall_with_error_handle(header + data)
  File "C:\Users\natth\AppData\Roaming\Python\Python312\site-packages\wandb\sdk\lib\sock_client.py", line 130, in _sendall_with_error_handle
    sent = self._sock.send(data)
           ^^^^^^^^^^^^^^^^^^^^^
ConnectionAbortedError: [WinError 10053] An established connection was aborted by the software in your host machine
